def foo() do
    #ERROR:
    foo(1,2)

    return 1
end



